Workbook

Sheet Stakeholder Register
B2: Stakeholder Register
B3: Northbridge Digital Banking Platform Upgrade · PRJ-2026-0147
B5: ID | C5: Stakeholder (role) | D5: Org | E5: RACI | F5: What they need | G5: Power | H5: Interest | I5: Engagement approach
B6: SH-01 | C6: VP Digital Banking (Sponsor) | D6: Northbridge | E6: A | F6: Confidence the platform lands on time and on budget | G6: High | H6: High | I6: Weekly 1:1; approves CRs >$25K; owns go/no-go
B7: SH-02 | C7: Head of Retail Banking (Business Owner) | D7: Northbridge | E7: A | F7: Design sign-off; UAT acceptance | G7: High | H7: High | I7: Design & UAT gates; monthly steering
B8: SH-03 | C8: IT Delivery Lead | D8: Northbridge | E8: R | F8: Build progress; environment readiness | G8: Medium | H8: High | I8: Daily stand-up; weekly delivery review
B9: SH-04 | C9: SI Partner Engagement Manager (Meridian) | D9: Meridian SI | E9: R | F9: Clear scope; timely approvals; invoice sign-off | G9: Medium | H9: High | I9: Weekly delivery call; monthly commercial review
B10: SH-05 | C10: Finance Business Partner | D10: Northbridge | E10: C | F10: Accurate spend, accruals and forecast | G10: Medium | H10: High | I10: Monthly cost review; validates EAC before steering
B11: SH-06 | C11: Risk & Compliance (OSFI B-13) | D11: Northbridge | E11: C | F11: Evidence of technology-risk controls | G11: High | H11: Medium | I11: Gate reviews at design and pre-go-live
B12: SH-07 | C12: Procurement | D12: Northbridge | E12: C | F12: PO compliance; no invoices without a PO | G12: Low | H12: Medium | I12: Ad-hoc; receives the PO-compliance exception log
B13: SH-08 | C13: PCO (Keshaav Gite) | D13: Northbridge | E13: R | F13: Runs schedule, cost, RAID, reporting | G13: — | H13: — | I13: Owns the governance cadence

Sheet Budget
B2: Approved Budget — by cost category by month
B3: Baselined 2026-01-15. Figures in CAD. Total BAC $1,260,000.
B5: Cost Category | C5: Jan | D5: Feb | E5: Mar | F5: Apr | G5: May | H5: Jun | I5: Jul | J5: Aug | K5: Sep | L5: Oct | M5: Nov | N5: Dec | O5: Total Budget
B6: SI Partner Fees | C6: 12600 | D6: 21000 | E6: 33600 | F6: 42000 | G6: 50400 | H6: 50400 | I6: 50400 | J6: 46200 | K6: 42000 | L6: 37800 | M6: 21000 | N6: 12600 | O6: =SUM(C6:N6) -> 420000
B7: Internal Labour | C7: 15600 | D7: 18200 | E7: 20800 | F7: 23400 | G7: 23400 | H7: 23400 | I7: 23400 | J7: 23400 | K7: 23400 | L7: 23400 | M7: 20800 | N7: 20800 | O7: =SUM(C7:N7) -> 260000
B8: Contractor Labour | C8: 3600 | D8: 7200 | E8: 14400 | F8: 21600 | G8: 25200 | H8: 25200 | I8: 25200 | J8: 21600 | K8: 18000 | L8: 10800 | M8: 5400 | N8: 1800 | O8: =SUM(C8:N8) -> 180000
B9: Software Licences | C9: 43500 | D9: 7250 | E9: 7250 | F9: 7250 | G9: 7250 | H9: 7250 | I9: 7250 | J9: 7250 | K9: 7250 | L9: 14500 | M9: 14500 | N9: 14500 | O9: =SUM(C9:N9) -> 145000
B10: Hardware & Infra | C10: 4500 | D10: 18000 | E10: 27000 | F10: 18000 | G10: 9000 | H10: 4500 | I10: 2700 | J10: 1800 | K10: 1800 | L10: 900 | M10: 900 | N10: 900 | O10: =SUM(C10:N10) -> 90000
B11: Cloud / Hosting | C11: 1200 | D11: 2400 | E11: 3600 | F11: 4800 | G11: 6000 | H11: 6000 | I11: 6000 | J11: 6000 | K11: 6000 | L11: 6000 | M11: 6000 | N11: 6000 | O11: =SUM(C11:N11) -> 60000
B12: Training & Change | C12: 0 | D12: 0 | E12: 0 | F12: 500 | G12: 1250 | H12: 2000 | I12: 2500 | J12: 3750 | K12: 6250 | L12: 6250 | M12: 1750 | N12: 750 | O12: =SUM(C12:N12) -> 25000
B13: Travel | C13: 1200 | D13: 1200 | E13: 1200 | F13: 960 | G13: 960 | H13: 960 | I13: 960 | J13: 960 | K13: 960 | L13: 960 | M13: 840 | N13: 840 | O13: =SUM(C13:N13) -> 12000
B14: Contingency | C14: 3400 | D14: 3400 | E14: 5440 | F14: 5440 | G14: 6800 | H14: 6800 | I14: 6800 | J14: 6800 | K14: 6800 | L14: 6800 | M14: 4760 | N14: 4760 | O14: =SUM(C14:N14) -> 68000
B15: TOTAL | C15: =SUM(C6:C14) -> 85600 | D15: =SUM(D6:D14) -> 78650 | E15: =SUM(E6:E14) -> 113290 | F15: =SUM(F6:F14) -> 123950 | G15: =SUM(G6:G14) -> 130260 | H15: =SUM(H6:H14) -> 126510 | I15: =SUM(I6:I14) -> 125210 | J15: =SUM(J6:J14) -> 117760 | ... O15: =SUM(O6:O14) -> 1260000
B17: Cumulative Plan | C17: =SUM($C$15:C15) -> 85600 | D17: =SUM($C$15:D15) -> 164250 | E17: =SUM($C$15:E15) -> 277540 | F17: =SUM($C$15:F15) -> 401490 | G17: =SUM($C$15:G15) -> 531750 | H17: =SUM($C$15:H15) -> 658260 | I17: =SUM($C$15:I15) -> 783470 | J17: =SUM($C$15:J15) -> 901230 | ... N17: =SUM($C$15:N15) -> 1260000

Sheet Actuals (D365 Export)
B2: Actuals — Accounts Payable transaction export
B3: Source: Dynamics 365 Finance · AP vendor transactions · exported 2026-09-01
B5: Posting Date | C5: Voucher | D5: Vendor ID | E5: Vendor Name | F5: Invoice No | G5: PO Ref | H5: Cost Category | I5: Description | J5: Amount | K5: Currency | L5: Status
B6: 2026-04-19 | C6: AP-500020 | D6: V-10166 | E6: Vantage Consulting Associates | F6: INV-8819 | G6: PO-2026-1032 | H6: Contractor Labour | I6: Senior developer - monthly | J6: 14377.74 | K6: CAD | L6: Posted
B7: 2026-08-28 | C7: GJ-500110 | E7: (Internal journal) | H7: Internal Labour | I7: Internal labour recharge - monthly | J7: 23548.67 | K7: CAD | L7: Posted
B8: 2026-07-17 | C8: AP-500084 | D8: V-10133 | E8: Keystone Training Partners | F8: INV-8883 | G8: PO-2026-1017 | H8: Training & Change | I8: End-user training materials | J8: 1378.95 | K8: CAD | L8: Posted
B9: 2026-01-24 | C9: AP-500034 | D9: V-10102 | E9: Northgate Software Licensing | F9: INV-8833 | G9: PO-2026-1062 | H9: Software Licences | I9: API gateway licence | J9: 12883.3 | K9: CAD | L9: Posted
B10: 2026-07-11 | C10: AP-500028 | D10: V-10078 | E10: Ironwood Contracting Group | F10: INV-8827 | G10: PO-2026-1067 | H10: Contractor Labour | I10: Solution architect - part time | J10: 14754.12 | K10: CAD | L10: Posted
B11: 2026-07-11 | C11: AP-500099 | D11: V-10150 | E11: Harbourview Travel Management | F11: INV-8898 | G11: PO-2026-1010 | H11: Travel | I11: Vendor site visit | J11: 460.75 | K11: CAD | L11: Posted
B12: 2026-03-13 | C12: AP-500067 | D12: V-10044 | E12: Cascade Cloud Services Inc | F12: INV-8866 | G12: PO-2026-1035 | H12: Cloud / Hosting | I12: Compute - monthly usage | J12: 2019.1 | K12: CAD | L12: Posted
B13: 2026-04-18 | C13: AP-500094 | D13: V-10150 | E13: Harbourview Travel Management | F13: INV-8893 | G13: PO-2026-1028 | H13: Travel | I13: Vendor site visit | J13: 438.8 | K13: CAD | L13: Posted
B14: 2026-04-12 | C14: AP-500051 | D14: V-10119 | E14: Summit Hardware Solutions | F14: INV-8850 | G14: PO-2026-1020 | H14: Hardware & Infra | I14: Storage expansion | J14: 6100.62 | K14: CAD | L14: Posted
B15: 2026-02-28 | C15: GJ-500104 | E15: (Internal journal) | H15: Internal Labour | I15: Internal labour recharge - monthly | J15: 18171.13 | K15: CAD | L15: Posted
B16: 2026-07-25 | C16: AP-500012 | D16: V-10021 | E16: Meridian Systems Integration Ltd | F16: INV-8811 | G16: PO-2026-1087 | H16: SI Partner Fees | I16: Sprint delivery - milestone billing | J16: 26526.18 | K16: CAD | L16: Posted
B17: 2026-03-25 | C17: AP-500006 | D17: V-10021 | E17: Meridian Systems Integration Ltd | F17: INV-8805 | G17: PO-2026-1054 | H17: SI Partner Fees | I17: Integration build - phase billing | J17: 36944.61 | K17: CAD | L17: Posted
B18: 2026-07-28 | C18: GJ-500109 | E18: (Internal journal) | H18: Internal Labour | I18: Internal labour recharge - monthly | J18: 23215.93 | K18: CAD | L18: Posted
B19: 2026-06-15 | C19: AP-500098 | D19: V-10150 | E19: Harbourview Travel Management | F19: INV-8897 | G19: PO-2026-1041 | H19: Travel | I19: Onsite integration workshop | J19: 297.49 | K19: CAD | L19: Posted
B20: 2026-05-20 | C20: AP-500008 | D20: V-10021 | E20: Meridian Systems Integration Ltd | F20: INV-8807 | G20: PO-2026-1015 | H20: SI Partner Fees | I20: UAT support services | J20: 25864.07 | K20: CAD | L20: Posted
B21: 2026-08-03 | C21: AP-500102 | D21: V-10150 | E21: Harbourview Travel Management | F21: INV-8901 | G21: PO-2026-1079 | H21: Travel | I21: Onsite integration workshop | J21: 449.64 | K21: CAD | L21: Posted
B22: 2026-05-14 | C22: AP-500115 | D22: V-10102 | E22: Northgate Software Licensing | F22: INV-8905 | G22: PO-2026-1044 | H22: Software Licences | I22: US licence true-up (USD invoice) | J22: 14900 | K22: USD | L22: Posted
B23: 2026-02-20 | C23: AP-500004 | D23: V-10021 | E23: Meridian Systems Integration Ltd | F23: INV-8803 | G23: PO-2026-1025 | H23: SI Partner Fees | I23: Cutover support | J23: 9118.08 | K23: CAD | L23: Posted
B24: 2026-06-10 | C24: AP-500083 | D24: V-10133 | E24: Keystone Training Partners | F24: INV-8882 | G24: PO-2026-1022 | H24: Training & Change | I24: Change readiness workshops | J24: 527.24 | K24: CAD | L24: Posted
B25: 2026-01-09 | C25: AP-500016 | D25: V-10166 | E25: Vantage Consulting Associates | F25: INV-8815 | G25: PO-2026-1083 | H25: Contractor Labour | I25: Solution architect - part time | J25: 4228.79 | K25: CAD | L25: Posted
B26: 2026-05-11 | C26: AP-500054 | D26: V-10119 | E26: Summit Hardware Solutions | F26: INV-8853 | G26: PO-2026-1036 | H26: Hardware & Infra | I26: Network switch upgrade | J26: 2242.85 | K26: CAD | L26: Posted
B27: 2026-08-26 | C27: AP-500114 | D27: V-10044 | E27: Cascade Cloud Services Inc | F27: INV-8904 | G27: PO-2026-1014 | H27: Cloud / Hosting | I27: Awaiting approval | J27: 5820 | K27: CAD | L27: Pending
B28: 2026-08-24 | C28: AP-500029 | D28: V-10166 | E28: Vantage Consulting Associates | F28: INV-8828 | G28: PO-2026-1083 | H28: Contractor Labour | I28: Data migration specialist | J28: 9561.23 | K28: CAD | L28: Posted
B29: 2026-06-11 | C29: AP-500042 | D29: V-10102 | E29: Northgate Software Licensing | F29: INV-8841 | G29: PO-2026-1058 | H29: Software Licences | I29: Monitoring suite subscription | J29: 7794 | K29: CAD | L29: Posted
B30: 2026-01-10 | C30: AP-500032 | D30: V-10102 | E30: Northgate Software Licensing | F30: INV-8831 | G30: PO-2026-1008 | H30: Software Licences | I30: Core platform licence - annual | J30: 13873.17 | K30: CAD | L30: Posted
... B36: 2026-05-20 | C36: AP-500009 | D36: V-10021 | E36: Meridian Systems Integration Ltd | F36: INV-8808 | G36: PO-2026-1037 | H36: SI Partner Fees | I36: Cutover support | J36: 27884.56 | K36: CAD | L36: Posted
B37: 2026-05-28 | C37: GJ-500107 | E37: (Internal journal) | H37: Internal Labour | I37: Internal labour recharge - monthly | J37: 23350.91 | K37: CAD | L37: Posted
B38: 2026-08-24 | C38: AP-500014 | D38: V-10021 | E38: Meridian Systems Integration Ltd | F38: INV-8813 | G38: PO-2026-1041 | H38: SI Partner Fees | I38: Sprint delivery - milestone billing | J38: 21772.4 | K38: CAD | L38: Posted
B39: 2026-02-09 | C39: AP-500035 | D39: V-10102 | E39: Northgate Software Licensing | F39: INV-8834 | G39: PO-2026-1012 | H39: Software Licences | I39: Core platform licence - annual | J39: 2603.16 | K39: CAD | L39: Posted
B40: 2026-01-10 | C40: AP-500002 | D40: V-10021 | E40: Meridian Systems Integration Ltd | F40: INV-8801 | G40: PO-2026-1017 | H40: SI Partner Fees | I40: Sprint delivery - milestone billing | J40: 14684.44 | K40: CAD | L40: Posted
B41: 2026-02-26 | C41: AP-500037 | D41: V-10102 | E41: Northgate Software Licensing | F41: INV-8836 | G41: PO-2026-1006 | H41: Software Licences | I41: Core platform licence - annual | J41: 2498.84 | K41: CAD | L41: Posted
B42: 2026-03-16 | C42: AP-500039 | D42: V-10102 | E42: Northgate Software Licensing | F42: INV-8838 | G42: PO-2026-1023 | H42: Software Licences | I42: Monitoring suite subscription | J42: 2924.58 | K42: CAD | L42: Posted
B43: 2026-07-25 | C43: AP-500059 | D43: V-10119 | E43: Summit Hardware Solutions | F43: INV-8858 | G43: PO-2026-1019 | H43: Hardware & Infra | I43: Application server refresh | J43: 1053.8 | K43: CAD | L43: Posted
B44: 2026-08-20 | C44: AP-500085 | D44: V-10133 | E44: Keystone Training Partners | F44: INV-8884 | G44: PO-2026-1057 | H44: Training & Change | I44: Super-user training cohort | J44: 651.5 | K44: CAD | L44: Posted
B45: 2026-02-14 | C45: AP-500018 | D45: V-10166 | E45: Vantage Consulting Associates | F45: INV-8817 | G45: PO-2026-1028 | H45: Contractor Labour | I45: QA analyst - monthly | J45: 4315.39 | K45: CAD | L45: Posted
B46: 2026-06-14 | C46: AP-500072 | D46: V-10044 | E46: Cascade Cloud Services Inc | F46: INV-8871 | G46: PO-2026-1055 | H46: Cloud / Hosting | I46: Compute - monthly usage | J46: 2440.58 | K46: CAD | L46: Posted
B47: 2026-03-27 | C47: AP-500092 | D47: V-10150 | E47: Harbourview Travel Management | F47: INV-8891 | G47: PO-2026-1073 | H47: Travel | I47: Vendor site visit | J47: 519.02 | K47: CAD | L47: Posted
...

Sheet Committed POs
B2: Committed Costs — open purchase orders
B3: POs raised, goods/services not yet invoiced. THIS is what juniors forget.
B5: PO Number | C5: Vendor ID | D5: Vendor Name | E5: Cost Category | F5: Description | G5: Committed Amount | H5: Expected Delivery | I5: Status
B6: PO-2026-1088 | C6: V-10021 | D6: Meridian Systems Integration Ltd | E6: SI Partner Fees | F6: Sprint 9-10 delivery | G6: 78000 | H6: 2026-09-30 | I6: Open
B7: PO-2026-1091 | C7: V-10078 | D7: Ironwood Contracting Group | E7: Contractor Labour | F7: Sep-Nov contractor extension | G7: 64500 | H7: 2026-11-30 | I7: Open
B8: PO-2026-1094 | C8: V-10102 | D8: Northgate Software Licensing | E8: Software Licences | F8: Production licence uplift | G8: 32000 | H8: 2026-10-15 | I8: Open
B9: PO-2026-1096 | C9: V-10133 | D9: Keystone Training Partners | E9: Training & Change | F9: End-user training delivery | G9: 18500 | H9: 2026-10-31 | I9: Open
B10: PO-2026-1099 | C10: V-10044 | D10: Cascade Cloud Services Inc | E10: Cloud / Hosting | F10: Prod environment - Sep to Dec | G10: 21600 | H10: 2026-12-31 | I10: Open
F11: TOTAL COMMITTED | G11: =SUM(G6:G10) -> 214600

Sheet Cost Dashboard
B2: Cost Control Dashboard — Budget · Actual · Committed · EAC
B3: Period ending 31 Aug 2026 (Month 8 of 12). FX: USD invoices converted @1.36.
B5: Cost Category | C5: Budget (BAC) | D5: YTD Budget | E5: Actual (posted) | F5: Committed (PO) | G5: Est. to Complete | H5: Forecast (EAC) | I5: Variance at Completion | J5: Var %
B6: SI Partner Fees | C6: =Budget!O6 -> 420000 | D6: =SUM(Budget!C6:J6) -> 306600 | E6: =SUMIFS('Actuals (D365 Export)'!$J$6:$J$119,'Actuals (D365 Export)'!$H$6:$H$119,$B6,'Actuals (D365 Export)'!$L$6:$L$119,"Posted",'Actuals (D365 Export)'!$K$6:$K$119,"CAD")+SUMIFS('Actuals (D365 Export)'!$J$6:$J$119,'Actuals (D365 Export)'!$H$6:$H$119,$B6,'Actuals (D365 Export)'!$L$6:$L$119,"Posted",'Actuals (D365 Export)'!$K$6:$K$119,"USD")*1.36 -> 323968.73 | F6: =SUMIF('Committed POs'!$E$6:$E$10,$B6,'Committed POs'!$G$6:$G$10) -> 78000 | G6: =MAX(C6-D6-F6,0) -> 35400 | H6: =E6+F6+G6 -> 437368.73 | I6: =C6-H6 -> -17368.73 | J6: =IF(C6=0,0,I6/C6) -> -0.041354119
B7: Internal Labour | C7: =Budget!O7 -> 260000 | D7: =SUM(Budget!C7:J7) -> 171600 | E7: =SUMIFS('Actuals (D365 Export)'!$J$6:$J$119,'Actuals (D365 Export)'!$H$6:$H$119,$B7,'Actuals (D365 Export)'!$L$6:$L$119,"Posted",'Actuals (D365 Export)'!$K$6:$K$119,"CAD")+SUMIFS('Actuals (D365 Export)'!$J$6:$J$119,'Actuals (D365 Export)'!$H$6:$H$119,$B7,'Actuals (D365 Export)'!$L$6:$L$119,"Posted",'Actuals (D365 Export)'!$K$6:$K$119,"USD")*1.36 -> 171047.1 | F7: =SUMIF('Committed POs'!$E$6:$E$10,$B7,'Committed POs'!$G$6:$G$10) -> 0 | G7: =MAX(C7-D7-F7,0) -> 88400 | H7: =E7+F7+G7 -> 259447.1 | I7: =C7-H7 -> 552.9 | J7: =IF(C7=0,0,I7/C7) -> 0.0021265385
B8: Contractor Labour | C8: =Budget!O8 -> 180000 | D8: =SUM(Budget!C8:J8) -> 144000 | E8: =SUMIFS('Actuals (D365 Export)'!$J$6:$J$119,'Actuals (D365 Export)'!$H$6:$H$119,$B8,'Actuals (D365 Export)'!$L$6:$L$119,"Posted",'Actuals (D365 Export)'!$K$6:$K$119,"CAD")+SUMIFS('Actuals (D365 Export)'!$J$6:$J$119,'Actuals (D365 Export)'!$H$6:$H$119,$B8,'Actuals (D365 Export)'!$L$6:$L$119,"Posted",'Actuals (D365 Export)'!$K$6:$K$119,"USD")*1.36 -> 179550.05 | F8: =SUMIF('Committed POs'!$E$6:$E$10,$B8,'Committed POs'!$G$6:$G$10) -> 64500 | G8: =MAX(C8-D8-F8,0) -> 0 | H8: =E8+F8+G8 -> 244050.05 | I8: =C8-H8 -> -64050.05 | J8: =IF(C8=0,0,I8/C8) -> -0.35583361
B9: Software Licences | C9: =Budget!O9 -> 145000 | D9: =SUM(Budget!C9:J9) -> 94250 | E9: =SUMIFS('Actuals (D365 Export)'!$J$6:$J$119,'Actuals (D365 Export)'!$H$6:$H$119,$B9,'Actuals (D365 Export)'!$L$6:$L$119,"Posted",'Actuals (D365 Export)'!$K$6:$K$119,"CAD")+SUMIFS('Actuals (D365 Export)'!$J$6:$J$119,'Actuals (D365 Export)'!$H$6:$H$119,$B9,'Actuals (D365 Export)'!$L$6:$L$119,"Posted",'Actuals (D365 Export)'!$K$6:$K$119,"USD")*1.36 -> 112919.36 | F9: =SUMIF('Committed POs'!$E$6:$E$10,$B9,'Committed POs'!$G$6:$G$10) -> 32000 | G9: =MAX(C9-D9-F9,0) -> 18750 | H9: =E9+F9+G9 -> 163669.36 | I9: =C9-H9 -> -18669.36 | J9: =IF(C9=0,0,I9/C9) -> -0.12875421
B10: Hardware & Infra | C10: =Budget!O10 -> 90000 | D10: =SUM(Budget!C10:J10) -> 85500 | E10: =SUMIFS('Actuals (D365 Export)'!$J$6:$J$119,'Actuals (D365 Export)'!$H$6:$H$119,$B10,'Actuals (D365 Export)'!$L$6:$L$119,"Posted",'Actuals (D365 Export)'!$K$6:$K$119,"CAD")+SUMIFS('Actuals (D365 Export)'!$J$6:$J$119,'Actuals (D365 Export)'!$H$6:$H$119,$B10,'Actuals (D365 Export)'!$L$6:$L$119,"Posted",'Actuals (D365 Export)'!$K$6:$K$119,"USD")*1.36 -> 60880.94 | F10: =SUMIF('Committed POs'!$E$6:$E$10,$B10,'Committed POs'!$G$6:$G$10) -> 0 | G10: =MAX(C10-D10-F10,0) -> 4500 | H10: =E10+F10+G10 -> 65380.94 | I10: =C10-H10 -> 24619.06 | J10: =IF(C10=0,0,I10/C10) -> 0.27354511
B11: Cloud / Hosting | C11: =Budget!O11 -> 60000 | D11: =SUM(Budget!C11:J11) -> 36000 | E11: =SUMIFS('Actuals (D365 Export)'!$J$6:$J$119,'Actuals (D365 Export)'!$H$6:$H$119,$B11,'Actuals (D365 Export)'!$L$6:$L$119,"Posted",'Actuals (D365 Export)'!$K$6:$K$119,"CAD")+SUMIFS('Actuals (D365 Export)'!$J$6:$J$119,'Actuals (D365 Export)'!$H$6:$H$119,$B11,'Actuals (D365 Export)'!$L$6:$L$119,"Posted",'Actuals (D365 Export)'!$K$6:$K$119,"USD")*1.36 -> 38800.06 | F11: =SUMIF('Committed POs'!$E$6:$E$10,$B11,'Committed POs'!$G$6:$G$10) -> 21600 | G11: =MAX(C11-D11-F11,0) -> 2400 | H11: =E11+F11+G11 -> 62800.06 | I11: =C11-H11 -> -2800.06 | J11: =IF(C11=0,0,I11/C11) -> -0.046667667
B12: Training & Change | C12: =Budget!O12 -> 25000 | D12: =SUM(Budget!C12:J12) -> 10000 | E12: =SUMIFS('Actuals (D365 Export)'!$J$6:$J$119,'Actuals (D365 Export)'!$H$6:$H$119,$B12,'Actuals (D365 Export)'!$L$6:$L$119,"Posted",'Actuals (D365 Export)'!$K$6:$K$119,"CAD")+SUMIFS('Actuals (D365 Export)'!$J$6:$J$119,'Actuals (D365 Export)'!$H$6:$H$119,$B12,'Actuals (D365 Export)'!$L$6:$L$119,"Posted",'Actuals (D365 Export)'!$K$6:$K$119,"USD")*1.36 -> 5578.96 | F12: =SUMIF('Committed POs'!$E$6:$E$10,$B12,'Committed POs'!$G$6:$G$10) -> 18500 | G12: =MAX(C12-D12-F12,0) -> 0 | H12: =E12+F12+G12 -> 24078.96 | I12: =C12-H12 -> 921.04 | J12: =IF(C12=0,0,I12/C12) -> 0.0368416
B13: Travel | C13: =Budget!O13 -> 12000 | D13: =SUM(Budget!C13:J13) -> 8400 | E13: =SUMIFS('Actuals (D365 Export)'!$J$6:$J$119,'Actuals (D365 Export)'!$H$6:$H$119,$B13,'Actuals (D365 Export)'!$L$6:$L$119,"Posted",'Actuals (D365 Export)'!$K$6:$K$119,"CAD")+SUMIFS('Actuals (D365 Export)'!$J$6:$J$119,'Actuals (D365 Export)'!$H$6:$H$119,$B13,'Actuals (D365 Export)'!$L$6:$L$119,"Posted",'Actuals (D365 Export)'!$K$6:$K$119,"USD")*1.36 -> 7945.62 | F13: =SUMIF('Committed POs'!$E$6:$E$10,$B13,'Committed POs'!$G$6:$G$10) -> 0 | G13: =MAX(C13-D13-F13,0) -> 3600 | H13: =E13+F13+G13 -> 11545.62 | I13: =C13-H13 -> 454.38 | J13: =IF(C13=0,0,I13/C13) -> 0.037865
B14: Contingency | C14: =Budget!O14 -> 68000 | D14: =SUM(Budget!C14:J14) -> 44880 | E14: =SUMIFS('Actuals (D365 Export)'!$J$6:$J$119,'Actuals (D365 Export)'!$H$6:$H$119,$B14,'Actuals (D365 Export)'!$L$6:$L$119,"Posted",'Actuals (D365 Export)'!$K$6:$K$119,"CAD")+SUMIFS('Actuals (D365 Export)'!$J$6:$J$119,'Actuals (D365 Export)'!$H$6:$H$119,$B14,'Actuals (D365 Export)'!$L$6:$L$119,"Posted",'Actuals (D365 Export)'!$K$6:$K$119,"USD")*1.36 -> 0 | F14: =SUMIF('Committed POs'!$E$6:$E$10,$B14,'Committed POs'!$G$6:$G$10) -> 0 | G14: =MAX(C14-D14-F14,0) -> 23120 | H14: =E14+F14+G14 -> 23120 | I14: =C14-H14 -> 44880 | J14: =IF(C14=0,0,I14/C14) -> 0.66
B15: TOTAL | C15: =SUM(C6:C14) -> 1260000 | D15: =SUM(D6:D14) -> 901230 | E15: =SUM(E6:E14) -> 900690.82 | F15: =SUM(F6:F14) -> 214600 | G15: =SUM(G6:G14) -> 176170 | H15: =SUM(H6:H14) -> 1291460.8 | I15: =SUM(I6:I14) -> -31460.82 | J15: =I15/C15 -> -0.024968905
B17: HEADLINE
B18: Budget at Completion (BAC) | E18: =C15 -> 1260000
B19: Actual to date (posted) | E19: =E15 -> 900690.82
B20: % of budget spent | E20: =E15/C15 -> 0.71483398
B21: YTD variance (Actual vs YTD Budget) | E21: =D15-E15 -> 539.18
B22: Committed (open POs) | E22: =F15 -> 214600
B23: Unposted invoices (pending) | E23: =SUMIFS('Actuals (D365 Export)'!$J$6:$J$119,'Actuals (D365 Export)'!$L$6:$L$119,"Pending") -> 28220
B24: Forecast at Completion (EAC) | E24: =H15 -> 1291460.8
B25: VARIANCE AT COMPLETION | E25: =I15 -> -31460.82
B26: Contingency remaining | E26: =C14-H14 -> 44880
B27: COST RAG | E27: =IF(I15>=0,"GREEN",IF(ABS(I15/C15)<0.05,"AMBER","RED")) -> AMBER
B30: S-Curve data (cumulative)
B31: Month | C31: Cumulative Plan | D31: Cumulative Actual
B32: Jan | C32: =SUM(Budget!$C$15:C$15) -> 85600 | D32: =SUMPRODUCT((TEXT('Actuals (D365 Export)'!$C$6:$C$119,"mmm")="Jan")*('Actuals (D365 Export)'!$L$6:$L$119="Posted")*'Actuals (D365 Export)'!$J$6:$J$119) -> 0
B33: Feb | C33: =SUM(Budget!$C$15:D$15) -> 164250 | D33: =D32+SUMPRODUCT((TEXT('Actuals (D365 Export)'!$C$6:$C$119,"mmm")="Feb")*('Actuals (D365 Export)'!$L$6:$L$119="Posted")*'Actuals (D365 Export)'!$J$6:$J$119) -> 0
B34: Mar | C34: =SUM(Budget!$C$15:E$15) -> 277540 | D34: =D33+SUMPRODUCT((TEXT('Actuals (D365 Export)'!$C$6:$C$119,"mmm")="Mar")*('Actuals (D365 Export)'!$L$6:$L$119="Posted")*'Actuals (D365 Export)'!$J$6:$J$119) -> 0
B35: Apr | C35: =SUM(Budget!$C$15:F$15) -> 401490 | D35: =D34+SUMPRODUCT((TEXT('Actuals (D365 Export)'!$C$6:$C$119,"mmm")="Apr")*('Actuals (D365 Export)'!$L$6:$L$119="Posted")*'Actuals (D365 Export)'!$J$6:$J$119) -> 0
B36: May | C36: =SUM(Budget!$C$15:G$15) -> 531750 | D36: =D35+SUMPRODUCT((TEXT('Actuals (D365 Export)'!$C$6:$C$119,"mmm")="May")*('Actuals (D365 Export)'!$L$6:$L$119="Posted")*'Actuals (D365 Export)'!$J$6:$J$119) -> 0
B37: Jun | C37: =SUM(Budget!$C$15:H$15) -> 658260 | D37: =D36+SUMPRODUCT((TEXT('Actuals (D365 Export)'!$C$6:$C$119,"mmm")="Jun")*('Actuals (D365 Export)'!$L$6:$L$119="Posted")*'Actuals (D365 Export)'!$J$6:$J$119) -> 0
B38: Jul | C38: =SUM(Budget!$C$15:I$15) -> 783470 | D38: =D37+SUMPRODUCT((TEXT('Actuals (D365 Export)'!$C$6:$C$119,"mmm")="Jul")*('Actuals (D365 Export)'!$L$6:$L$119="Posted")*'Actuals (D365 Export)'!$J$6:$J$119) -> 0
B39: Aug | C39: =SUM(Budget!$C$15:J$15) -> 901230 | D39: =D38+SUMPRODUCT((TEXT('Actuals (D365 Export)'!$C$6:$C$119,"mmm")="Aug")*('Actuals (D365 Export)'!$L$6:$L$119="Posted")*'Actuals (D365 Export)'!$J$6:$J$119) -> 0
B40: Sep | C40: =SUM(Budget!$C$15:K$15) -> 1013690
B41: Oct | C41: =SUM(Budget!$C$15:L$15) -> 1121100
B42: Nov | C42: =SUM(Budget!$C$15:M$15) -> 1197050
B43: Dec | C43: =SUM(Budget!$C$15:N$15) -> 1260000

Sheet RAID Log
B2: RAID Log
B3: Risks · Assumptions · Issues · Dependencies. Reviewed weekly; High items escalated to steering.
B5: ID | C5: Type | D5: Description | E5: Owner | F5: Impact | G5: Mitigation / Response | H5: Status | I5: Raised
B6: I-001 | C6: Issue | D6: Contractor Labour is tracking 22% over plan ($179.5K actual vs $144K YTD budget). Forecast to land $64K over at completion. | E6: IT Delivery Lead | F6: High | G6: Root cause: two extra contractors onboarded in Mar to recover the integration build. CR-003 raised to draw down contingency. Rate card renegotiation underway. | H6: Open | I6: 2026-06-12
B7: I-002 | C7: Issue | D7: Duplicate invoice detected in the D365 AP export — same invoice number posted against two vouchers. | E7: Finance Business Partner | F7: Medium | G7: Flagged to AP; credit/reversal requested. Excluded from the EAC pending correction. Root cause: manual re-key after a failed batch. | H7: Open | I7: 2026-08-14
B8: I-003 | C8: Issue | D8: One hardware invoice posted with NO PO reference — breaches procurement policy (no-PO-no-pay). | E8: Procurement | F8: Medium | G8: Retrospective PO raised; exception logged. Control added: monthly PO-compliance check on the AP export. | H8: Open | I8: 2026-07-22
B9: I-004 | C9: Issue | D9: Two vendor invoices ($28.2K) remain unposted/pending approval at month-end — understating reported actuals. | E9: Finance Business Partner | F9: Medium | G9: Tracked separately on the dashboard; will be accrued into the August position so the month is not understated. | H9: Open | I9: 2026-08-29
B10: R-001 | C10: Risk | D10: SI partner (Meridian) has slipped delivery on two prior engagements. Sprint 9-10 ($78K PO) is on the critical path to UAT. | E10: SI Engagement Mgr | F10: High | G10: Milestone-based billing with 10% holdback; weekly delivery call; recovery plan required if any sprint slips >3 days. | H10: Open | I10: 2026-02-10
B11: R-002 | C11: Risk | D11: UAT window (Oct) overlaps with the retail quarter-end close — business testers may be unavailable. | E11: Business Owner | F11: High | G11: Testers pre-booked; backup super-users identified; CR-004 requests a 2-week UAT extension. | H11: Mitigated | I11: 2026-05-18
B12: R-003 | C12: Risk | D12: USD-denominated licence invoices expose the project to FX movement (currently ~$14.9K USD posted). | E12: Finance Business Partner | F12: Low | G12: FX rate fixed at 1.36 for forecasting; exposure is immaterial (<2% of budget). Monitor quarterly. | H12: Open | I12: 2026-05-14
B13: R-004 | C13: Risk | D13: Contingency ($68K) may be exhausted by the contractor overrun, leaving no buffer for cutover issues. | E13: PCO | F13: High | G13: Contingency drawdown tracked; $44.9K remains. No further drawdown without sponsor approval (per CR governance). | H13: Open | I13: 2026-08-01
B14: A-001 | C14: Assumption | D14: Business testers are available for the full UAT window outside quarter-end. | E14: Business Owner | F14: Medium | G14: Confirmed at kickoff; being re-tested — see R-002. If it fails, the go-live date moves. | H14: Open | I14: 2026-01-15
B15: A-002 | C15: Assumption | D15: No further regulatory (OSFI B-13) requirements land before go-live. | E15: Risk & Compliance | F15: Medium | G15: Confirmed with Risk & Compliance at the design gate. Re-verified quarterly. | H15: Open | I15: 2026-01-15
B16: D-001 | C16: Dependency | D16: GL opening-balance load depends on Finance closing the FY25 books. | E16: Finance Business Partner | F16: High | G16: Confirmed complete 2026-03-20. Load proceeded on schedule. | H16: Closed | I16: 2026-01-20
B17: D-002 | C17: Dependency | D17: Production cutover depends on the Infrastructure team completing the network upgrade. | E17: IT Delivery Lead | F17: High | G17: Scheduled for Oct; tracked on the schedule as a hard predecessor to cutover. | H17: Open | I17: 2026-04-02

Sheet Change Control Log
B2: Change Control Log
B3: Every change to baselined scope, cost or schedule. Sponsor approves >$25K.
B5: CR ID | C5: Change requested | D5: Raised by | E5: Cost impact | F5: Sched. | G5: Priority | H5: Status | I5: Approver | J5: Decided | K5: Rationale / decision note
B6: CR-001 | C6: Add real-time payment notifications to scope | D6: Business Owner | E6: +$46,000 | F6: +10d | G6: Medium | H6: Approved | I6: VP Digital Banking | J6: 2026-03-06 | K6: Competitive necessity. Funded from contingency; sponsor approved at March steering.
B7: CR-002 | C7: Defer wealth-module integration to Phase 2 | D7: IT Delivery Lead | E7: -$38,000 | F7: -15d | G7: Medium | H7: Approved | I7: VP Digital Banking | J7: 2026-04-17 | K7: De-scoped to protect the go-live date. Credit returned to contingency.
B8: CR-003 | C8: Draw down $64K contingency to cover contractor overrun | D8: PCO | E8: $0 (net) | F8: 0 | G8: High | H8: Approved | I8: VP Digital Banking | J8: 2026-08-20 | K8: Contingency exists for exactly this. Rate renegotiation to prevent recurrence. Links to I-001.
B9: CR-004 | C9: Extend UAT window by 2 weeks (quarter-end clash) | D9: Business Owner | E9: +$12,000 | F9: +10d | G9: High | H9: Under Review | I9: VP Digital Banking | J9: — | K9: Protects test quality over the date. Links to R-002. Decision due at Sept steering.
B10: CR-005 | C10: Upgrade to premium support tier for hypercare | D10: SI Engagement Mgr | E10: +$28,000 | F10: 0 | G10: Low | H10: REJECTED | I10: VP Digital Banking | J10: 2026-07-30 | K10: Standard support is contractually sufficient for a 2-week hypercare. Not justified.
B11: CR-006 | C11: Add OSFI B-13 evidence pack to deliverables | D11: Risk & Compliance | E11: +$8,500 | F11: +3d | G11: High | H11: Approved | I11: VP Digital Banking | J11: 2026-02-25 | K11: Regulatory — non-negotiable. Absorbed within contingency.

Sheet Action Register
B2: Action Item Register
B3: Every action traces to a RAID or CR ID.
B5: ID | C5: Action | D5: Ref (RAID/CR) | E5: Owner | F5: Raised | G5: Due | H5: Status | I5: Notes
B6: AI-001 | C6: Renegotiate contractor rate card with Ironwood | D6: I-001 | E6: IT Delivery Lead | F6: 2026-06-12 | G6: 2026-09-15 | H6: In Progress | I6: Draft terms received; 8% reduction offered.
B7: AI-002 | C7: Obtain credit note for the duplicate invoice | D7: I-002 | E7: Finance Business Partner | F7: 2026-08-14 | G7: 2026-09-10 | H7: In Progress | I7: Vendor acknowledged; credit expected in Sept.
B8: AI-003 | C8: Raise retrospective PO for the no-PO hardware invoice | D8: I-003 | E8: Procurement | F8: 2026-07-22 | G8: 2026-08-05 | H8: Closed | I8: PO-2026-1087 raised; exception logged.
B9: AI-004 | C9: Add monthly PO-compliance check to the cost process | D9: I-003 | E9: PCO | F9: 2026-07-22 | G9: 2026-08-31 | H9: Closed | I9: Control added to the month-end checklist.
B10: AI-005 | C10: Accrue the two pending invoices into the August position | D10: I-004 | E10: PCO | F10: 2026-08-29 | G10: 2026-09-05 | H10: Open | I10: $28.2K to be accrued so August is not understated.
B11: AI-006 | C11: Confirm UAT tester availability against quarter-end | D11: R-002/A-001 | E11: Business Owner | F11: 2026-05-18 | G11: 2026-09-12 | H11: Open | I11: Drives the CR-004 decision at Sept steering.
B12: AI-007 | C12: Prepare contingency drawdown paper for sponsor | D12: I-001/CR-003 | E12: PCO | F12: 2026-08-01 | G12: 2026-08-18 | H12: Closed | I12: Approved at August steering.
B13: AI-008 | C13: Confirm network upgrade completion date with Infrastructure | D13: D-002 | E13: IT Delivery Lead | F13: 2026-04-02 | G13: 2026-09-30 | H13: Open | I13: Hard predecessor to cutover.

Sheet Decision Log
B2: Decision Log
B3: What was decided, by whom, and WHY — so nobody re-litigates it in month nine.
B5: ID | C5: Date | D5: Decision | E5: Decided by | F5: Rationale
B6: DEC-01 | C6: 2026-03-06 | D6: Add real-time payment notifications (CR-001), funded from contingency. | E6: VP Digital Banking | F6: Competitors launched the feature; going live without it would require an immediate follow-up release. Cheaper to absorb now.
B7: DEC-02 | C7: 2026-04-17 | D7: Defer the wealth module to Phase 2 (CR-002). | E7: VP Digital Banking | F7: Protects the go-live date. The module serves 4% of customers; the delay is acceptable to the business.
B8: DEC-03 | C8: 2026-08-20 | D8: Draw down $64K contingency to cover the contractor overrun (CR-003). | E8: VP Digital Banking | F8: Contingency exists for exactly this. The alternative — cutting scope late — carries more risk than the cost.
B9: DEC-04 | C9: 2026-07-30 | D9: Reject the premium support upgrade (CR-005). | E9: VP Digital Banking | F9: Standard support is contractually sufficient for a 2-week hypercare. Not justified on evidence.
B10: DEC-05 | C10: 2026-08-29 | D10: Report the project AMBER on cost despite a near-zero YTD variance. | E10: PCO / Sponsor | F10: YTD actuals look on-plan, but adding $214.6K of committed POs forecasts a $31K overrun. Reporting Green on YTD alone would have been misleading.

Sheet Milestone Tracker
B2: Milestone Tracker
B3: Baseline vs Forecast vs Actual. Slippage in working days. Source: MS Project schedule.
B5: ID | C5: Milestone | D5: Baseline | E5: Forecast | F5: Actual | G5: Slip (days) | H5: Status
B6: M1 | C6: Project approved & funded | D6: 2026-01-15 | E6: 2026-01-15 | F6: 2026-01-15 | G6: 0 | H6: Met
B7: M2 | C7: Design baselined | D7: 2026-03-12 | E7: 2026-03-12 | F7: 2026-03-18 | G7: 4 | H7: Met (late)
B8: M3 | C8: Build complete | D8: 2026-07-09 | E8: 2026-07-09 | F8: 2026-07-16 | G8: 5 | H8: Met (late)
B9: M4 | C9: UAT signed off | D9: 2026-10-15 | E9: 2026-10-29 | F9: — | G9: 10 | H9: At Risk
B10: M5 | C10: GO-LIVE | D10: 2026-11-05 | E10: 2026-11-19 | F10: — | G10: 10 | H10: At Risk
B11: M6 | C11: Project closed | D11: 2026-11-26 | E11: 2026-12-10 | F11: — | G11: 10 | H11: At Risk
B13: Note: the 10-day slip on M4-M6 is driven by CR-004 (UAT extension, under review). If CR-004 is approved, these become the new baseline.

Sheet Status Report
B2: Status Report — Period ending 31 Aug 2026
B3: Northbridge Digital Banking Platform Upgrade · PRJ-2026-0147 · Month 8 of 12 · For September Steering Committee
B5: Overall | C5: AMBER
B6: Schedule | C6: AMBER
B7: Cost | C7: AMBER
B8: Scope | C8: GREEN
B9: Quality | C9: GREEN
B10: Cost Amber: YTD spend is on plan, but $214.6K of committed POs forecasts a $31.5K overrun at completion. Contingency covers it — see CR-003.
B11: Schedule Amber: 10-day forecast slip to go-live, driven by the UAT window clash with quarter-end (R-002 / CR-004, under review).
B13: Cost position
B14: • Budget (BAC) $1,260,000 · Actual to date $900,691 (71.5% spent) · Committed $214,600 · Forecast (EAC) $1,291,461.
B15: • YTD variance is effectively nil (-0.1%) — but that is not the story. Adding committed POs, the project forecasts $31,461 OVER budget (-2.5%).
B16: • Driver: Contractor Labour, 22% over plan (I-001) — two extra contractors onboarded in March to recover the integration build.
B17: • Contingency of $44,880 remains after the CR-003 drawdown — sufficient to absorb the overrun. No additional funding requested.
B19: Accomplished this period
B20: • Build complete (M3) — 5 days late, absorbed without impacting UAT start.
B21: • Vendor master, open AP and GL opening balances migrated and reconciled.
B22: • CR-003 (contingency drawdown) approved at August steering; contractor rate renegotiation underway (AI-001).
B24: Planned next period
... B37: • R-002 (High, Mitigated): UAT / quarter-end clash — CR-004 raised.
